multiprocessing.pool.RemoteTraceback: 
"""
Traceback (most recent call last):
  File "/cvmfs/hpc.rug.nl/versions/2023.01/rocky8/x86_64/amd/zen3/software/Python/3.11.5-GCCcore-13.2.0/lib/python3.11/multiprocessing/pool.py", line 125, in worker
    result = (True, func(*args, **kwds))
                    ^^^^^^^^^^^^^^^^^^^
  File "/cvmfs/hpc.rug.nl/versions/2023.01/rocky8/x86_64/amd/zen3/software/Python/3.11.5-GCCcore-13.2.0/lib/python3.11/multiprocessing/pool.py", line 51, in starmapstar
    return list(itertools.starmap(args[0], args[1]))
           ^^^^^^^^^^^^^^^^^^^^^^^^^^^^^^^^^^^^^^^^^
  File "/home3/p319950/ResearchProject/data_exporter.py", line 38, in data_export
    cosm_data = cosm_setup.lensing_spectra(*cosm_par)
                ^^^^^^^^^^^^^^^^^^^^^^^^^^^^^^^^^^^^^
  File "/home3/p319950/ResearchProject/cosm_setup.py", line 104, in __init__
    self.k_nls, self.zs_for_k_nls_used = self._k_nl_exact_nonfid(self.zs_for_k_nls, 30000, k_nls_fiducial, zs_used_fiducial)
                                         ^^^^^^^^^^^^^^^^^^^^^^^^^^^^^^^^^^^^^^^^^^^^^^^^^^^^^^^^^^^^^^^^^^^^^^^^^^^^^^^^^^^
  File "/home3/p319950/ResearchProject/cosm_setup.py", line 249, in _k_nl_exact_nonfid
    raise Exception(f'more than 50 iterations required for z = {z}, l_lower = {l_lower}, l_upper = {l_upper}, error = {error}, result = {result}')
Exception: more than 50 iterations required for z = 232.43243243243245, l_lower = 1e-08, l_upper = 5080.071518055699, error = 0.8001836778307818, result = 5080.071518055699
"""

The above exception was the direct cause of the following exception:

Traceback (most recent call last):
  File "/home3/p319950/ResearchProject/data_exporter.py", line 246, in <module>
    pool.starmap(data_export, exports)
  File "/cvmfs/hpc.rug.nl/versions/2023.01/rocky8/x86_64/amd/zen3/software/Python/3.11.5-GCCcore-13.2.0/lib/python3.11/multiprocessing/pool.py", line 375, in starmap
    return self._map_async(func, iterable, starmapstar, chunksize).get()
           ^^^^^^^^^^^^^^^^^^^^^^^^^^^^^^^^^^^^^^^^^^^^^^^^^^^^^^^^^^^^^
  File "/cvmfs/hpc.rug.nl/versions/2023.01/rocky8/x86_64/amd/zen3/software/Python/3.11.5-GCCcore-13.2.0/lib/python3.11/multiprocessing/pool.py", line 774, in get
    raise self._value
Exception: more than 50 iterations required for z = 232.43243243243245, l_lower = 1e-08, l_upper = 5080.071518055699, error = 0.8001836778307818, result = 5080.071518055699
